Workbook

Sheet サマリー
A1: 就活生アンケート分析 サマリー
B3: 【背景】 | C3: 就活支援のためのアンケート（就活前学生 142件／就活経験者 6件）
B4: 【目的】 | C4: 就活生の悩みと、役立つ支援内容を明らかにする
B5: 【表記】 | C5: グラフはすべて青系で統一表示
A7: 調査概要
B8: 項目 | C8: 就活前学生 | D8: 就活経験者
B9: 回答者数 | C9: =就活前_集計!$B$4 -> 142 | D9: =就活経験者_集計!$B$4 -> 6
B10: 最多学年/卒業年度 | C10: 1年生（88.0%） | D10: 28卒（100%）
B11: 就活未着手の割合 | C11: =就活前_集計!$C$20 -> 0.8943662 | D11: ―
B12: 県内就職に興味あり（とても＋少し） | C12: =(就活前_集計!$B$34+就活前_集計!$B$35)/就活前_集計!$B$4 -> 0.57746479 | D12: ―
B13: 実際の県内就職割合 | C13: ― | D13: =就活経験者_集計!$C$35 -> 0.16666667
B14: 最大の不安（面接） | C14: =就活前_集計!$C$48 -> 0.88028169 | D14: ―
A16: 重要インサイト（5点） ― 根拠データを強調グラフで表示
B17: ① 面接不安は圧倒的、かつ対策の効果も裏付けあり
B18: 就活前学生の88.0%(125人)が面接を不安視し、80.3%(114人)が面接対策を最も知りたいと回答。経験者調査でも「面接練習」が良かったこと1位(66.7%=4人)であり、対策の有効性が裏付けられる。
B19: 根拠データ（グラフ）
B20: 項目 | C20: 割合
B21: 就活前：面接が不安 | C21: =就活前_集計!$C$48 -> 0.88028169
B22: 経験者：面接練習をして良かった | C22: =就活経験者_集計!$C$80 -> 0.66666667
B30: ② 早期着手の重要性が経験者側からも明確
B31: 就活前学生の89.4%(127人)が「まだ何も始めていない」。経験者は大学3年後半に本格開始が66.7%(4人)で最多だが、「就活開始が遅かった」ことを後悔する声も33.3%(2人)あり、早期の意識づけが有効と示唆される。
B32: 根拠データ（グラフ）
B33: 項目 | C33: 割合
B34: 就活前：まだ何も始めていない | C34: =就活前_集計!$C$20 -> 0.8943662
B35: 経験者：3年後半に本格開始 | C35: =就活経験者_集計!$C$65 -> 0.66666667
B36: 経験者：開始が遅かったと後悔 | C36: =就活経験者_集計!$C$96 -> 0.33333333
B44: ③ 「地元志向」と実際の就職先にギャップ
B45: 就活前学生の57.7%が県内就職に興味を示す一方、経験者で実際に県内就職したのは16.7%(1人)のみ、83.3%(5人)は県外へ。地域選択理由は「給与・待遇」「企業の魅力」が各50%(3人)で最多、地元志向だけでは決め手にならない現実が見える。
B46: 根拠データ（グラフ）
B47: 項目 | C47: 割合
B48: 就活前：県内就職に興味あり | C48: =就活前_集計!$C$34+就活前_集計!$C$35 -> 0.57746479
B49: 経験者：実際に県内就職 | C49: =就活経験者_集計!$C$35 -> 0.16666667
B57: ④ 「ガクチカ・志望動機」の重要性と支援コンテンツのギャップ
B58: 経験者の面接で最頻出の質問は「学生時代に力を入れたこと」「志望動機」で共に100%(6人)。一方、就活前学生向けアンケートの選択肢にはガクチカ対策が明示項目として存在せず、支援ニーズが見えにくい形で潜在している。
B59: 根拠データ（グラフ）
B60: 項目 | C60: 割合
B61: 経験者：ガクチカを質問された | C61: =就活経験者_集計!$C$113 -> 1
B62: 経験者：志望動機を質問された | C62: =就活経験者_集計!$C$114 -> 1
B70: ⑤ 「給与・待遇」重視の企業選びと知りたい情報が一致
B71: 就活前学生の企業選び重視項目は給与74.6%(106人)が1位、岡山企業について知りたい情報でも給与79.6%(113人)が1位。経験者の地域選択理由でも「給与・待遇」が50%(3人)で最多タイであり、待遇情報の透明性が意思決定を左右する。
...

Sheet 就活前_集計
A1: 就活前学生向けアンケート 集計（n=142）
A3: Q1. 学年を教えてください
A4: 回答者数(n) | B4: 142
A5: 項目 | B5: 回答数 | C5: 割合
A6: 1年生 | B6: 125 | C6: =B6/$B$4 -> 0.88028169
A7: 2年生 | B7: 9 | C7: =B7/$B$4 -> 0.063380282
A8: 3〜4年生・院生（計） | B8: 8 | C8: =B8/$B$4 -> 0.056338028
A9: ※3〜4年生・大学院生は個別内訳が非表示のため合算
A17: Q2. 現在の就活状況を教えてください
A18: 回答者数(n) | B18: 142
A19: 項目 | B19: 回答数 | C19: 割合
A20: まだ何も始めていない | B20: 127 | C20: =B20/$B$18 -> 0.8943662
A21: 情報収集中・準備中など（計） | B21: 15 | C21: =B21/$B$18 -> 0.1056338
A22: ※「まだ何も始めていない」以外は個別内訳が非表示のため合算
A31: Q3. 岡山県内での就職に興味はありますか
A32: 回答者数(n) | B32: 142
A33: 項目 | B33: 回答数 | C33: 割合
A34: とてもある | B34: 25 | C34: =B34/$B$32 -> 0.17605634
A35: 少しある | B35: 57 | C35: =B35/$B$32 -> 0.40140845
A36: あまりない | B36: 48 | C36: =B36/$B$32 -> 0.33802817
A37: ない | B37: 12 | C37: =B37/$B$32 -> 0.084507042
A45: Q4. 就活で不安なこと（複数選択可）
A46: 回答者数(n) | B46: 142
A47: 項目 | B47: 回答数 | C47: 割合
A48: 面接 | B48: 125 | C48: =B48/$B$46 -> 0.88028169
A49: 自己分析 | B49: 83 | C49: =B49/$B$46 -> 0.58450704
A50: ES（エントリーシート） | B50: 76 | C50: =B50/$B$46 -> 0.53521127
A51: グループディスカッション | B51: 73 | C51: =B51/$B$46 -> 0.51408451
A52: マナー | B52: 70 | C52: =B52/$B$46 -> 0.49295775
A53: インターンシップ | B53: 60 | C53: =B53/$B$46 -> 0.42253521
A54: 企業研究 | B54: 53 | C54: =B54/$B$46 -> 0.37323944
A55: SPI・適性検査 | B55: 45 | C55: =B55/$B$46 -> 0.31690141
A56: 業界研究 | B56: 45 | C56: =B56/$B$46 -> 0.31690141
A57: その他 | B57: 2 | C57: =B57/$B$46 -> 0.014084507
A58: ※複数選択のため割合は回答者数(142)に対する割合
A63: Q5. 就活を始める前に知りたいこと（複数選択可）
A64: 回答者数(n) | B64: 142
A65: 項目 | B65: 回答数 | C65: 割合
A66: 面接対策 | B66: 114 | C66: =B66/$B$64 -> 0.8028169
A67: 就活スケジュール | B67: 108 | C67: =B67/$B$64 -> 0.76056338
...

Sheet 就活経験者_集計
A1: 就活経験者向けアンケート 集計（n=6）
A3: Q1. 卒業年度を教えてください
A4: 回答者数(n) | B4: 6
A5: 項目 | B5: 回答数 | C5: 割合
A6: 28卒 | B6: 6 | C6: =B6/$B$4 -> 1
A17: Q2. 就職先の業界を教えてください
A18: 回答者数(n) | B18: 6
A19: 項目 | B19: 回答数 | C19: 割合
A20: 公務員 | B20: 3 | C20: =B20/$B$18 -> 0.5
A21: IT | B21: 1 | C21: =B21/$B$18 -> 0.16666667
A22: メーカー | B22: 1 | C22: =B22/$B$18 -> 0.16666667
A23: 金融 | B23: 1 | C23: =B23/$B$18 -> 0.16666667
A31: Q3. 就職先はどこですか
A32: 回答者数(n) | B32: 6
A33: 項目 | B33: 回答数 | C33: 割合
A34: 岡山県外 | B34: 5 | C34: =B34/$B$32 -> 0.83333333
A35: 岡山県内 | B35: 1 | C35: =B35/$B$32 -> 0.16666667
A45: Q4. なぜその地域を選びましたか（複数選択可）
A46: 回答者数(n) | B46: 6
A47: 項目 | B47: 回答数 | C47: 割合
A48: 給与・待遇が良かった | B48: 3 | C48: =B48/$B$46 -> 0.5
A49: 企業の魅力を感じた | B49: 3 | C49: =B49/$B$46 -> 0.5
A50: 地元で働きたかった | B50: 2 | C50: =B50/$B$46 -> 0.33333333
A51: 家族の近くにいたかった | B51: 1 | C51: =B51/$B$46 -> 0.16666667
A52: 働きやすい環境があった | B52: 1 | C52: =B52/$B$46 -> 0.16666667
A53: 交通アクセスが良かった | B53: 1 | C53: =B53/$B$46 -> 0.16666667
A54: 特に理由はない | B54: 1 | C54: =B54/$B$46 -> 0.16666667
A55: 希望する業界・職種の求人があった | B55: 0 | C55: =B55/$B$46 -> 0
A56: 生活コストが低い地域を選んだ | B56: 0 | C56: =B56/$B$46 -> 0
A57: ※複数選択のため割合は回答者数(6)に対する割合
A62: Q5. 就活を本格的に始めた時期を教えてください
A63: 回答者数(n) | B63: 6
A64: 項目 | B64: 回答数 | C64: 割合
A65: 大学3年後半 | B65: 4 | C65: =B65/$B$63 -> 0.66666667
A66: 大学3年前半 | B66: 1 | C66: =B66/$B$63 -> 0.16666667
A67: 大学4年前半 | B67: 1 | C67: =B67/$B$63 -> 0.16666667
A76: Q6. やっておいて良かったこと（複数選択可）
A77: 回答者数(n) | B77: 6
A78: 項目 | B78: 回答数 | C78: 割合
A79: インターン参加 | B79: 4 | C79: =B79/$B$77 -> 0.66666667
...

Sheet 比較・示唆
A1: 就活前学生 × 就活経験者 比較
A2: ※ グラフはすべて青系で統一表示
A3: 地域（岡山県内就職）に関する意識と実態の比較
A4: 観点 | B4: 就活前学生(n=142) | C4: 就活経験者(n=6) | D4: 差分・示唆
A5: 県内就職への関心・実態 | B5: =就活前_集計!$C$34+就活前_集計!$C$35 -> 0.57746479 | C5: =就活経験者_集計!$C$35 -> 0.16666667 | D5: 興味はあっても実際の選択は県外が多数。給与・待遇など具体的魅力訴求が必要
A7: 地域選択で「給与・待遇」を重視する割合 | B7: =就活前_集計!$C$83 -> 0.74647887 | C7: =就活経験者_集計!$C$48 -> 0.5 | D7: 両者とも給与・待遇を重視。待遇情報の可視化が有効
A9: 面接を不安視/対策して良かったとする割合 | B9: =就活前_集計!$C$48 -> 0.88028169 | C9: =就活経験者_集計!$C$80 -> 0.66666667 | D9: 面接対策への支援ニーズが一貫して高い
A12: 共通して重視される項目 Top5（就活前学生：企業選び基準）
A13: 項目 | B13: 回答数 | C13: 割合
A14: 給与 | B14: =就活前_集計!$B$83 -> 106 | C14: =B14/142 -> 0.74647887
A15: 仕事内容 | B15: =就活前_集計!$B$84 -> 77 | C15: =B15/142 -> 0.54225352
A16: 人間関係 | B16: =就活前_集計!$B$85 -> 75 | C16: =B16/142 -> 0.52816901
A17: 福利厚生 | B17: =就活前_集計!$B$86 -> 63 | C17: =B17/142 -> 0.44366197
A18: ワークライフバランス | B18: =就活前_集計!$B$87 -> 62 | C18: =B18/142 -> 0.43661972
